<robot name="myrobot">

<link name="base_footprint"/>
<link name="base_link">
    <inertial>
        <origin xyz="0.0 0.0 0.0" rpy="0.0 0.0 0.0"/>
        <mass value="1.0"/>
        <inertia ixx="0.4" ixy="0.0" ixz="0.0"
                 iyy="0.4" iyz="0.0"
                 izz="0.2"/>
    </inertial>
    <visual name="">
        <origin xyz="0.0 0.0 0.0" rpy="0.0 0.0 0.0"/>
        <geometry>
            <box size="0.3 0.3 0.3"/>
        </geometry>
        <material name="">
            <color rgba="1.0 0.0 0.0 1.0"/>
            <texture filename=""/>
        </material>
    </visual>
    <collision>
        <origin xyz="0.0 0.0 0.0" rpy="0.0 0.0 0.0"/>
        <geometry>
            <box size="0.0 0.0 0.0"/>
        </geometry>
    </collision>
</link>

<joint name="base_joint" type="fixed">
    <origin xyz="0.0 0.0 0.135" rpy="0.0 0.0 0.0"/>
    <parent link="base_footprint"/>
    <child link="base_link"/>
    <axis xyz="0.0 0.0 0.0"/>
</joint>

<!-- wheel right> -->

<link name="wheel_right_link">
    <inertial>
        <origin xyz="0.0 0.0 0.0" rpy="0.0 0.0 0.0"/>
        <mass value="0.0"/>
        <inertia ixx="0.0" ixy="0.0" ixz="0.0" iyy="0.0" iyz="0.0" izz="0.0"/>
    </inertial>
    <visual name="">
        <origin xyz="0.5 0.0 0.0" rpy="1.57 0.0 0.0"/>
        <geometry>
            <cylinder radius="0.2" length="0.1"/>
        </geometry>
        <material name="">
            <color rgba="1.0 0.5 0.0 1.0"/>
            <texture filename=""/>
        </material>
    </visual>
    <collision>
        <origin xyz="0.0 0.0 0.0" rpy="0.0 0.0 0.0"/>
        <geometry>
            <box size="0.0 0.0 0.0"/>
        </geometry>
    </collision>
</link>

<joint name="wheel_right_joint" type="continuous">
    <origin xyz="0.25 0.4 0.0" rpy="1.57 0.0 0.0"/>
    <parent link="base_footprint"/>
    <child link="wheel_right_link"/>
    <axis xyz="1.0 0.0 0.0"/>
</joint>

<link name="wheel_left_link">
    <inertial>
        <origin xyz="0.0 0.0 0.0" rpy="0.0 0.0 0.0"/>
        <mass value="0.0"/>
        <inertia ixx="0.0" ixy="0.0" ixz="0.0" iyy="0.0" iyz="0.0" izz="0.0"/>
    </inertial>
    <visual name="">
        <origin xyz="0.5 0.0 0.0" rpy="1.57 0.0 0.0"/>
        <geometry>
            <sphere radius="0.2"/>
        </geometry>
        <material name="">
            <color rgba="1.0 0.5 0.0 1.0"/>
            <texture filename=""/>
        </material>
    </visual>
    <collision>
        <origin xyz="0.0 0.0 0.0" rpy="0.0 0.0 0.0"/>
        <geometry>
            <sphere radius="0.2"/>
        </geometry>
    </collision>
</link>

<joint name="wheel_left_joint" type="continuous">
    <origin xyz="1.0 0.4 0.0" rpy="1.57 0.0 0.0"/>
    <parent link="base_footprint"/>
    <child link="wheel_left_link"/>
    <axis xyz="1.0 0.0 0.0"/>
</joint>

</robot>